2018-03-11 17:37:56,735 INFO: RUMS startup [in /Users/User1/Documents/Proj/rums/app/__init__.py:43]
2018-03-11 17:38:02,970 ERROR: Exception on /edit_profile [POST] [in /Library/Python/2.7/site-packages/flask/app.py:1560]
Traceback (most recent call last):
  File "/Library/Python/2.7/site-packages/flask/app.py", line 1982, in wsgi_app
    response = self.full_dispatch_request()
  File "/Library/Python/2.7/site-packages/flask/app.py", line 1614, in full_dispatch_request
    rv = self.handle_user_exception(e)
  File "/Library/Python/2.7/site-packages/flask/app.py", line 1517, in handle_user_exception
    reraise(exc_type, exc_value, tb)
  File "/Library/Python/2.7/site-packages/flask/app.py", line 1612, in full_dispatch_request
    rv = self.dispatch_request()
  File "/Library/Python/2.7/site-packages/flask/app.py", line 1598, in dispatch_request
    return self.view_functions[rule.endpoint](**req.view_args)
  File "/Library/Python/2.7/site-packages/flask_login/utils.py", line 261, in decorated_view
    return func(*args, **kwargs)
  File "/Users/User1/Documents/Proj/rums/app/routes.py", line 83, in edit_profile
    db.session.commit()
  File "/Library/Python/2.7/site-packages/sqlalchemy/orm/scoping.py", line 153, in do
    return getattr(self.registry(), name)(*args, **kwargs)
  File "/Library/Python/2.7/site-packages/sqlalchemy/orm/session.py", line 943, in commit
    self.transaction.commit()
  File "/Library/Python/2.7/site-packages/sqlalchemy/orm/session.py", line 467, in commit
    self._prepare_impl()
  File "/Library/Python/2.7/site-packages/sqlalchemy/orm/session.py", line 447, in _prepare_impl
    self.session.flush()
  File "/Library/Python/2.7/site-packages/sqlalchemy/orm/session.py", line 2243, in flush
    self._flush(objects)
  File "/Library/Python/2.7/site-packages/sqlalchemy/orm/session.py", line 2369, in _flush
    transaction.rollback(_capture_exception=True)
  File "/Library/Python/2.7/site-packages/sqlalchemy/util/langhelpers.py", line 66, in __exit__
    compat.reraise(exc_type, exc_value, exc_tb)
  File "/Library/Python/2.7/site-packages/sqlalchemy/orm/session.py", line 2333, in _flush
    flush_context.execute()
  File "/Library/Python/2.7/site-packages/sqlalchemy/orm/unitofwork.py", line 391, in execute
    rec.execute(self)
  File "/Library/Python/2.7/site-packages/sqlalchemy/orm/unitofwork.py", line 556, in execute
    uow
  File "/Library/Python/2.7/site-packages/sqlalchemy/orm/persistence.py", line 177, in save_obj
    mapper, table, update)
  File "/Library/Python/2.7/site-packages/sqlalchemy/orm/persistence.py", line 768, in _emit_update_statements
    execute(statement, multiparams)
  File "/Library/Python/2.7/site-packages/sqlalchemy/engine/base.py", line 948, in execute
    return meth(self, multiparams, params)
  File "/Library/Python/2.7/site-packages/sqlalchemy/sql/elements.py", line 269, in _execute_on_connection
    return connection._execute_clauseelement(self, multiparams, params)
  File "/Library/Python/2.7/site-packages/sqlalchemy/engine/base.py", line 1060, in _execute_clauseelement
    compiled_sql, distilled_params
  File "/Library/Python/2.7/site-packages/sqlalchemy/engine/base.py", line 1200, in _execute_context
    context)
  File "/Library/Python/2.7/site-packages/sqlalchemy/engine/base.py", line 1413, in _handle_dbapi_exception
    exc_info
  File "/Library/Python/2.7/site-packages/sqlalchemy/util/compat.py", line 203, in raise_from_cause
    reraise(type(exception), exception, tb=exc_tb, cause=cause)
  File "/Library/Python/2.7/site-packages/sqlalchemy/engine/base.py", line 1193, in _execute_context
    context)
  File "/Library/Python/2.7/site-packages/sqlalchemy/engine/default.py", line 507, in do_execute
    cursor.execute(statement, parameters)
IntegrityError: (psycopg2.IntegrityError) duplicate key value violates unique constraint "ix_employee_username"
DETAIL:  Key (username)=(User2) already exists.
 [SQL: 'UPDATE employee SET username=%(username)s WHERE employee.employee_id = %(employee_employee_id)s'] [parameters: {'username': u'User2', 'employee_employee_id': 24}] (Background on this error at: http://sqlalche.me/e/gkpj)
2018-03-11 17:47:09,843 INFO: RUMS startup [in /Users/User1/Documents/Proj/rums/app/__init__.py:43]
2018-03-12 14:15:52,218 INFO: RUMS startup [in /Users/User1/Documents/Proj/rums/app/__init__.py:43]
2018-03-12 14:16:29,375 INFO: RUMS startup [in /Users/User1/Documents/Proj/rums/app/__init__.py:43]
2018-03-12 14:18:00,681 INFO: RUMS startup [in /Users/User1/Documents/Proj/rums/app/__init__.py:43]
2018-03-12 14:18:49,438 ERROR: Exception on /index [POST] [in /Library/Python/2.7/site-packages/flask/app.py:1560]
Traceback (most recent call last):
  File "/Library/Python/2.7/site-packages/flask/app.py", line 1982, in wsgi_app
    response = self.full_dispatch_request()
  File "/Library/Python/2.7/site-packages/flask/app.py", line 1614, in full_dispatch_request
    rv = self.handle_user_exception(e)
  File "/Library/Python/2.7/site-packages/flask/app.py", line 1517, in handle_user_exception
    reraise(exc_type, exc_value, tb)
  File "/Library/Python/2.7/site-packages/flask/app.py", line 1612, in full_dispatch_request
    rv = self.dispatch_request()
  File "/Library/Python/2.7/site-packages/flask/app.py", line 1598, in dispatch_request
    return self.view_functions[rule.endpoint](**req.view_args)
  File "/Library/Python/2.7/site-packages/flask_login/utils.py", line 261, in decorated_view
    return func(*args, **kwargs)
  File "/Users/User1/Documents/Proj/rums/app/routes.py", line 19, in index
    db.session.commit()
  File "/Library/Python/2.7/site-packages/sqlalchemy/orm/scoping.py", line 153, in do
    return getattr(self.registry(), name)(*args, **kwargs)
  File "/Library/Python/2.7/site-packages/sqlalchemy/orm/session.py", line 943, in commit
    self.transaction.commit()
  File "/Library/Python/2.7/site-packages/sqlalchemy/orm/session.py", line 467, in commit
    self._prepare_impl()
  File "/Library/Python/2.7/site-packages/sqlalchemy/orm/session.py", line 447, in _prepare_impl
    self.session.flush()
  File "/Library/Python/2.7/site-packages/sqlalchemy/orm/session.py", line 2243, in flush
    self._flush(objects)
  File "/Library/Python/2.7/site-packages/sqlalchemy/orm/session.py", line 2369, in _flush
    transaction.rollback(_capture_exception=True)
  File "/Library/Python/2.7/site-packages/sqlalchemy/util/langhelpers.py", line 66, in __exit__
    compat.reraise(exc_type, exc_value, exc_tb)
  File "/Library/Python/2.7/site-packages/sqlalchemy/orm/session.py", line 2333, in _flush
    flush_context.execute()
  File "/Library/Python/2.7/site-packages/sqlalchemy/orm/unitofwork.py", line 391, in execute
    rec.execute(self)
  File "/Library/Python/2.7/site-packages/sqlalchemy/orm/unitofwork.py", line 556, in execute
    uow
  File "/Library/Python/2.7/site-packages/sqlalchemy/orm/persistence.py", line 181, in save_obj
    mapper, table, insert)
  File "/Library/Python/2.7/site-packages/sqlalchemy/orm/persistence.py", line 866, in _emit_insert_statements
    execute(statement, params)
  File "/Library/Python/2.7/site-packages/sqlalchemy/engine/base.py", line 948, in execute
    return meth(self, multiparams, params)
  File "/Library/Python/2.7/site-packages/sqlalchemy/sql/elements.py", line 269, in _execute_on_connection
    return connection._execute_clauseelement(self, multiparams, params)
  File "/Library/Python/2.7/site-packages/sqlalchemy/engine/base.py", line 1060, in _execute_clauseelement
    compiled_sql, distilled_params
  File "/Library/Python/2.7/site-packages/sqlalchemy/engine/base.py", line 1200, in _execute_context
    context)
  File "/Library/Python/2.7/site-packages/sqlalchemy/engine/base.py", line 1413, in _handle_dbapi_exception
    exc_info
  File "/Library/Python/2.7/site-packages/sqlalchemy/util/compat.py", line 203, in raise_from_cause
    reraise(type(exception), exception, tb=exc_tb, cause=cause)
  File "/Library/Python/2.7/site-packages/sqlalchemy/engine/base.py", line 1193, in _execute_context
    context)
  File "/Library/Python/2.7/site-packages/sqlalchemy/engine/default.py", line 507, in do_execute
    cursor.execute(statement, parameters)
ProgrammingError: (psycopg2.ProgrammingError) can't adapt type 'builtin_function_or_method' [SQL: 'INSERT INTO time_record (employee_id, date, start_time, end_time, break_time, time_worked) VALUES (%(employee_id)s, %(date)s, %(start_time)s, %(end_time)s, %(break_time)s, %(time_worked)s) RETURNING time_record.time_record_id'] [parameters: {'employee_id': 22, 'start_time': datetime.time(10, 0), 'end_time': datetime.time(17, 0), 'time_worked': None, 'date': <built-in method today of type object at 0x10a4626e0>, 'break_time': datetime.time(1, 0)}] (Background on this error at: http://sqlalche.me/e/f405)
2018-03-12 15:47:45,637 INFO: RUMS startup [in /Users/User1/Documents/Proj/rums/app/__init__.py:43]
2018-03-12 15:48:18,817 ERROR: Exception on /index [POST] [in /Library/Python/2.7/site-packages/flask/app.py:1560]
Traceback (most recent call last):
  File "/Library/Python/2.7/site-packages/flask/app.py", line 1982, in wsgi_app
    response = self.full_dispatch_request()
  File "/Library/Python/2.7/site-packages/flask/app.py", line 1614, in full_dispatch_request
    rv = self.handle_user_exception(e)
  File "/Library/Python/2.7/site-packages/flask/app.py", line 1517, in handle_user_exception
    reraise(exc_type, exc_value, tb)
  File "/Library/Python/2.7/site-packages/flask/app.py", line 1612, in full_dispatch_request
    rv = self.dispatch_request()
  File "/Library/Python/2.7/site-packages/flask/app.py", line 1598, in dispatch_request
    return self.view_functions[rule.endpoint](**req.view_args)
  File "/Library/Python/2.7/site-packages/flask_login/utils.py", line 261, in decorated_view
    return func(*args, **kwargs)
  File "/Users/User1/Documents/Proj/rums/app/routes.py", line 16, in index
    worked = datetime.strptime(form.start_time.data) - datetime.strptime(form.end_time.data)
TypeError: strptime() takes exactly 2 arguments (1 given)
2018-03-12 15:50:49,417 INFO: RUMS startup [in /Users/User1/Documents/Proj/rums/app/__init__.py:43]
